Workbook

Sheet Dashboard
A1: Recruitment Dashboard
A2: All figures are formulas linked to the Candidates sheet. Data is synthetic.
A4: Screening SLA (days) | B4: 5 | C4: Edit B4: screening delays longer than this are highlighted on the Candidates sheet.
A5: Total candidates | B5: =COUNTA(Candidates!$A$2:$A$500) -> 120
A6: Active (In Progress) | B6: =COUNTIF(Candidates!$L$2:$L$500,"In Progress") -> 40
A7: Avg days to screen | B7: =IFERROR(AVERAGE(Candidates!$O$2:$O$500),0) -> 4.8205128
A8: Avg days to offer | B8: =IFERROR(AVERAGE(Candidates!$P$2:$P$500),0) -> 15.352941
A9: % screened within SLA | B9: =IFERROR(COUNTIFS(Candidates!$O$2:$O$500,"<="&B4)/COUNT(Candidates!$O$2:$O$500),0) -> 0.6025641
A11: Hiring funnel (reached at least this stage)
A12: Stage | B12: Stage # | C12: Candidates | D12: Step conversion | E12: Overall conversion
A13: Applied | B13: 1 | C13: =COUNTIF(Candidates!$N$2:$N$500,">="&B13) -> 120 | E13: =IFERROR(C13/C$13,0) -> 1
A14: Screened | B14: 2 | C14: =COUNTIF(Candidates!$N$2:$N$500,">="&B14) -> 78 | D14: =IFERROR(C14/C13,0) -> 0.65 | E14: =IFERROR(C14/C$13,0) -> 0.65
A15: Interviewed | B15: 3 | C15: =COUNTIF(Candidates!$N$2:$N$500,">="&B15) -> 47 | D15: =IFERROR(C15/C14,0) -> 0.6025641 | E15: =IFERROR(C15/C$13,0) -> 0.39166667
A16: Offered | B16: 4 | C16: =COUNTIF(Candidates!$N$2:$N$500,">="&B16) -> 17 | D16: =IFERROR(C16/C15,0) -> 0.36170213 | E16: =IFERROR(C16/C$13,0) -> 0.14166667
A17: Joined | B17: 5 | C17: =COUNTIF(Candidates!$N$2:$N$500,">="&B17) -> 6 | D17: =IFERROR(C17/C16,0) -> 0.35294118 | E17: =IFERROR(C17/C$13,0) -> 0.05
A20: Sourcing channel effectiveness
A21: Source | B21: Applicants | C21: Interviewed+ | D21: Offered+ | E21: Joined | F21: Interview rate | G21: Offer rate
A22: LinkedIn | B22: =COUNTIF(Candidates!$E$2:$E$500,A22) -> 35 | C22: =COUNTIFS(Candidates!$E$2:$E$500,A22,Candidates!$N$2:$N$500,">=3") -> 15 | D22: =COUNTIFS(Candidates!$E$2:$E$500,A22,Candidates!$N$2:$N$500,">=4") -> 4 | E22: =COUNTIFS(Candidates!$E$2:$E$500,A22,Candidates!$L$2:$L$500,"Joined") -> 1 | F22: =IFERROR(C22/B22,0) -> 0.42857143 | G22: =IFERROR(D22/B22,0) -> 0.11428571
A23: Job Portal | B23: =COUNTIF(Candidates!$E$2:$E$500,A23) -> 23 | C23: =COUNTIFS(Candidates!$E$2:$E$500,A23,Candidates!$N$2:$N$500,">=3") -> 10 | D23: =COUNTIFS(Candidates!$E$2:$E$500,A23,Candidates!$N$2:$N$500,">=4") -> 4 | E23: =COUNTIFS(Candidates!$E$2:$E$500,A23,Candidates!$L$2:$L$500,"Joined") -> 1 | F23: =IFERROR(C23/B23,0) -> 0.43478261 | G23: =IFERROR(D23/B23,0) -> 0.17391304
A24: Employee Referral | B24: =COUNTIF(Candidates!$E$2:$E$500,A24) -> 24 | C24: =COUNTIFS(Candidates!$E$2:$E$500,A24,Candidates!$N$2:$N$500,">=3") -> 10 | D24: =COUNTIFS(Candidates!$E$2:$E$500,A24,Candidates!$N$2:$N$500,">=4") -> 3 | E24: =COUNTIFS(Candidates!$E$2:$E$500,A24,Candidates!$L$2:$L$500,"Joined") -> 1 | F24: =IFERROR(C24/B24,0) -> 0.41666667 | G24: =IFERROR(D24/B24,0) -> 0.125
A25: Campus Drive | B25: =COUNTIF(Candidates!$E$2:$E$500,A25) -> 16 | C25: =COUNTIFS(Candidates!$E$2:$E$500,A25,Candidates!$N$2:$N$500,">=3") -> 3 | D25: =COUNTIFS(Candidates!$E$2:$E$500,A25,Candidates!$N$2:$N$500,">=4") -> 2 | E25: =COUNTIFS(Candidates!$E$2:$E$500,A25,Candidates!$L$2:$L$500,"Joined") -> 1 | F25: =IFERROR(C25/B25,0) -> 0.1875 | G25: =IFERROR(D25/B25,0) -> 0.125
A26: Company Website | B26: =COUNTIF(Candidates!$E$2:$E$500,A26) -> 22 | C26: =COUNTIFS(Candidates!$E$2:$E$500,A26,Candidates!$N$2:$N$500,">=3") -> 9 | D26: =COUNTIFS(Candidates!$E$2:$E$500,A26,Candidates!$N$2:$N$500,">=4") -> 4 | E26: =COUNTIFS(Candidates!$E$2:$E$500,A26,Candidates!$L$2:$L$500,"Joined") -> 2 | F26: =IFERROR(C26/B26,0) -> 0.40909091 | G26: =IFERROR(D26/B26,0) -> 0.18181818
A29: Outcome by role
A30: Role | B30: Applicants | C30: In Progress | D30: Rejected | E30: Withdrawn | F30: Joined
A31: Data Analyst Intern | B31: =COUNTIF(Candidates!$D$2:$D$500,A31) -> 16 | C31: =COUNTIFS(Candidates!$D$2:$D$500,$A31,Candidates!$L$2:$L$500,"In Progress") -> 7 | D31: =COUNTIFS(Candidates!$D$2:$D$500,$A31,Candidates!$L$2:$L$500,"Rejected") -> 9 | E31: =COUNTIFS(Candidates!$D$2:$D$500,$A31,Candidates!$L$2:$L$500,"Withdrawn") -> 0 | F31: =COUNTIFS(Candidates!$D$2:$D$500,$A31,Candidates!$L$2:$L$500,"Joined") -> 0
A32: Software Engineering Intern | B32: =COUNTIF(Candidates!$D$2:$D$500,A32) -> 25 | C32: =COUNTIFS(Candidates!$D$2:$D$500,$A32,Candidates!$L$2:$L$500,"In Progress") -> 4 | D32: =COUNTIFS(Candidates!$D$2:$D$500,$A32,Candidates!$L$2:$L$500,"Rejected") -> 16 | E32: =COUNTIFS(Candidates!$D$2:$D$500,$A32,Candidates!$L$2:$L$500,"Withdrawn") -> 3 | F32: =COUNTIFS(Candidates!$D$2:$D$500,$A32,Candidates!$L$2:$L$500,"Joined") -> 2
A33: Marketing Intern | B33: =COUNTIF(Candidates!$D$2:$D$500,A33) -> 20 | C33: =COUNTIFS(Candidates!$D$2:$D$500,$A33,Candidates!$L$2:$L$500,"In Progress") -> 5 | D33: =COUNTIFS(Candidates!$D$2:$D$500,$A33,Candidates!$L$2:$L$500,"Rejected") -> 9 | E33: =COUNTIFS(Candidates!$D$2:$D$500,$A33,Candidates!$L$2:$L$500,"Withdrawn") -> 5 | F33: =COUNTIFS(Candidates!$D$2:$D$500,$A33,Candidates!$L$2:$L$500,"Joined") -> 1
A34: Operations Intern | B34: =COUNTIF(Candidates!$D$2:$D$500,A34) -> 33 | C34: =COUNTIFS(Candidates!$D$2:$D$500,$A34,Candidates!$L$2:$L$500,"In Progress") -> 17 | D34: =COUNTIFS(Candidates!$D$2:$D$500,$A34,Candidates!$L$2:$L$500,"Rejected") -> 14 | E34: =COUNTIFS(Candidates!$D$2:$D$500,$A34,Candidates!$L$2:$L$500,"Withdrawn") -> 1 | F34: =COUNTIFS(Candidates!$D$2:$D$500,$A34,Candidates!$L$2:$L$500,"Joined") -> 1
A35: Finance Intern | B35: =COUNTIF(Candidates!$D$2:$D$500,A35) -> 26 | C35: =COUNTIFS(Candidates!$D$2:$D$500,$A35,Candidates!$L$2:$L$500,"In Progress") -> 7 | D35: =COUNTIFS(Candidates!$D$2:$D$500,$A35,Candidates!$L$2:$L$500,"Rejected") -> 13 | E35: =COUNTIFS(Candidates!$D$2:$D$500,$A35,Candidates!$L$2:$L$500,"Withdrawn") -> 4 | F35: =COUNTIFS(Candidates!$D$2:$D$500,$A35,Candidates!$L$2:$L$500,"Joined") -> 2

Sheet Candidates
A1: Candidate ID | B1: Name | C1: Email | D1: Role | E1: Source | F1: Recruiter | G1: Applied Date | H1: Screening Date | I1: Interview Date | J1: Offer Date | K1: Stage | L1: Outcome | M1: Notes | N1: Stage # | O1: Days to Screen | P1: Days to Offer
A2: C0001 | B2: Meera Sharma | C2: meera.sharma.1@example.com | D2: Finance Intern | E2: LinkedIn | F2: Recruiter B | G2: 46205 | H2: 46209 | I2: 46213 | K2: Interviewed | L2: Rejected | N2: =IFERROR(MATCH(K2,Lists!$A$2:$A$6,0),"") -> 3 | O2: =IF(OR(G2="",H2=""),"",H2-G2) -> 4 | P2: =IF(OR(G2="",J2=""),"",J2-G2)
A3: C0002 | B3: Diya Sharma | C3: diya.sharma.2@example.com | D3: Data Analyst Intern | E3: Employee Referral | F3: Recruiter C | G3: 46203 | K3: Applied | L3: Rejected | N3: =IFERROR(MATCH(K3,Lists!$A$2:$A$6,0),"") -> 1 | O3: =IF(OR(G3="",H3=""),"",H3-G3) | P3: =IF(OR(G3="",J3=""),"",J3-G3)
A4: C0003 | B4: Mira Nair | C4: mira.nair.3@example.com | D4: Data Analyst Intern | E4: Campus Drive | F4: Recruiter A | G4: 46249 | K4: Applied | L4: In Progress | N4: =IFERROR(MATCH(K4,Lists!$A$2:$A$6,0),"") -> 1 | O4: =IF(OR(G4="",H4=""),"",H4-G4) | P4: =IF(OR(G4="",J4=""),"",J4-G4)
A5: C0004 | B5: Riya Iyer | C5: riya.iyer.4@example.com | D5: Marketing Intern | E5: LinkedIn | F5: Recruiter B | G5: 46201 | K5: Applied | L5: Withdrawn | N5: =IFERROR(MATCH(K5,Lists!$A$2:$A$6,0),"") -> 1 | O5: =IF(OR(G5="",H5=""),"",H5-G5) | P5: =IF(OR(G5="",J5=""),"",J5-G5)
A6: C0005 | B6: Meera Iyer | C6: meera.iyer.5@example.com | D6: Operations Intern | E6: LinkedIn | F6: Recruiter B | G6: 46207 | H6: 46208 | I6: 46217 | J6: 46223 | K6: Offered | L6: In Progress | N6: =IFERROR(MATCH(K6,Lists!$A$2:$A$6,0),"") -> 4 | O6: =IF(OR(G6="",H6=""),"",H6-G6) -> 1 | P6: =IF(OR(G6="",J6=""),"",J6-G6) -> 16
A7: C0006 | B7: Zoya Chopra | C7: zoya.chopra.6@example.com | D7: Marketing Intern | E7: Company Website | F7: Recruiter A | G7: 46247 | H7: 46251 | I7: 46254 | J7: 46256 | K7: Offered | L7: Rejected | N7: =IFERROR(MATCH(K7,Lists!$A$2:$A$6,0),"") -> 4 | O7: =IF(OR(G7="",H7=""),"",H7-G7) -> 4 | P7: =IF(OR(G7="",J7=""),"",J7-G7) -> 9
A8: C0007 | B8: Meera Nair | C8: meera.nair.7@example.com | D8: Marketing Intern | E8: LinkedIn | F8: Recruiter B | G8: 46220 | K8: Applied | L8: In Progress | N8: =IFERROR(MATCH(K8,Lists!$A$2:$A$6,0),"") -> 1 | O8: =IF(OR(G8="",H8=""),"",H8-G8) | P8: =IF(OR(G8="",J8=""),"",J8-G8)
A9: C0008 | B9: Kabir Rao | C9: kabir.rao.8@example.com | D9: Marketing Intern | E9: Company Website | F9: Recruiter C | G9: 46242 | H9: 46246 | I9: 46250 | K9: Interviewed | L9: Rejected | N9: =IFERROR(MATCH(K9,Lists!$A$2:$A$6,0),"") -> 3 | O9: =IF(OR(G9="",H9=""),"",H9-G9) -> 4 | P9: =IF(OR(G9="",J9=""),"",J9-G9)
A10: C0009 | B10: Mira Mehta | C10: mira.mehta.9@example.com | D10: Operations Intern | E10: LinkedIn | F10: Recruiter A | G10: 46181 | H10: 46185 | I10: 46187 | K10: Interviewed | L10: Rejected | N10: =IFERROR(MATCH(K10,Lists!$A$2:$A$6,0),"") -> 3 | O10: =IF(OR(G10="",H10=""),"",H10-G10) -> 4 | P10: =IF(OR(G10="",J10=""),"",J10-G10)
A11: C0010 | B11: Aditya Chopra | C11: aditya.chopra.10@example.com | D11: Operations Intern | E11: LinkedIn | F11: Recruiter A | G11: 46201 | H11: 46209 | I11: 46217 | K11: Interviewed | L11: Rejected | N11: =IFERROR(MATCH(K11,Lists!$A$2:$A$6,0),"") -> 3 | O11: =IF(OR(G11="",H11=""),"",H11-G11) -> 8 | P11: =IF(OR(G11="",J11=""),"",J11-G11)
A12: C0011 | B12: Anaya Joshi | C12: anaya.joshi.11@example.com | D12: Operations Intern | E12: Job Portal | F12: Recruiter A | G12: 46207 | H12: 46214 | K12: Screened | L12: Rejected | N12: =IFERROR(MATCH(K12,Lists!$A$2:$A$6,0),"") -> 2 | O12: =IF(OR(G12="",H12=""),"",H12-G12) -> 7 | P12: =IF(OR(G12="",J12=""),"",J12-G12)
A13: C0012 | B13: Ishaan Khanna | C13: ishaan.khanna.12@example.com | D13: Software Engineering Intern | E13: Employee Referral | F13: Recruiter C | G13: 46180 | K13: Applied | L13: Rejected | N13: =IFERROR(MATCH(K13,Lists!$A$2:$A$6,0),"") -> 1 | O13: =IF(OR(G13="",H13=""),"",H13-G13) | P13: =IF(OR(G13="",J13=""),"",J13-G13)
A14: C0013 | B14: Riya Rao | C14: riya.rao.13@example.com | D14: Operations Intern | E14: Job Portal | F14: Recruiter C | G14: 46222 | K14: Applied | L14: Rejected | N14: =IFERROR(MATCH(K14,Lists!$A$2:$A$6,0),"") -> 1 | O14: =IF(OR(G14="",H14=""),"",H14-G14) | P14: =IF(OR(G14="",J14=""),"",J14-G14)
A15: C0014 | B15: Aarav Malik | C15: aarav.malik.14@example.com | D15: Operations Intern | E15: LinkedIn | F15: Recruiter A | G15: 46242 | H15: 46247 | I15: 46254 | K15: Interviewed | L15: In Progress | N15: =IFERROR(MATCH(K15,Lists!$A$2:$A$6,0),"") -> 3 | O15: =IF(OR(G15="",H15=""),"",H15-G15) -> 5 | P15: =IF(OR(G15="",J15=""),"",J15-G15)
A16: C0015 | B16: Arjun Bose | C16: arjun.bose.15@example.com | D16: Finance Intern | E16: Employee Referral | F16: Recruiter A | G16: 46238 | H16: 46240 | I16: 46246 | K16: Interviewed | L16: Rejected | N16: =IFERROR(MATCH(K16,Lists!$A$2:$A$6,0),"") -> 3 | O16: =IF(OR(G16="",H16=""),"",H16-G16) -> 2 | P16: =IF(OR(G16="",J16=""),"",J16-G16)
A17: C0016 | B17: Tara Kapoor | C17: tara.kapoor.16@example.com | D17: Finance Intern | E17: Job Portal | F17: Recruiter A | G17: 46241 | K17: Applied | L17: Withdrawn | N17: =IFERROR(MATCH(K17,Lists!$A$2:$A$6,0),"") -> 1 | O17: =IF(OR(G17="",H17=""),"",H17-G17) | P17: =IF(OR(G17="",J17=""),"",J17-G17)
A18: C0017 | B18: Meera Chopra | C18: meera.chopra.17@example.com | D18: Finance Intern | E18: Company Website | F18: Recruiter A | G18: 46213 | H18: 46217 | K18: Screened | L18: In Progress | N18: =IFERROR(MATCH(K18,Lists!$A$2:$A$6,0),"") -> 2 | O18: =IF(OR(G18="",H18=""),"",H18-G18) -> 4 | P18: =IF(OR(G18="",J18=""),"",J18-G18)
A19: C0018 | B19: Kiara Reddy | C19: kiara.reddy.18@example.com | D19: Software Engineering Intern | E19: Employee Referral | F19: Recruiter C | G19: 46242 | K19: Applied | L19: Rejected | N19: =IFERROR(MATCH(K19,Lists!$A$2:$A$6,0),"") -> 1 | O19: =IF(OR(G19="",H19=""),"",H19-G19) | P19: =IF(OR(G19="",J19=""),"",J19-G19)
A20: C0019 | B20: Isha Singh | C20: isha.singh.19@example.com | D20: Software Engineering Intern | E20: Campus Drive | F20: Recruiter B | G20: 46228 | H20: 46232 | K20: Screened | L20: Withdrawn | N20: =IFERROR(MATCH(K20,Lists!$A$2:$A$6,0),"") -> 2 | O20: =IF(OR(G20="",H20=""),"",H20-G20) -> 4 | P20: =IF(OR(G20="",J20=""),"",J20-G20)
A21: C0020 | B21: Tara Khanna | C21: tara.khanna.20@example.com | D21: Data Analyst Intern | E21: Employee Referral | F21: Recruiter A | G21: 46231 | H21: 46233 | I21: 46238 | J21: 46241 | K21: Offered | L21: In Progress | N21: =IFERROR(MATCH(K21,Lists!$A$2:$A$6,0),"") -> 4 | O21: =IF(OR(G21="",H21=""),"",H21-G21) -> 2 | P21: =IF(OR(G21="",J21=""),"",J21-G21) -> 10
A22: C0021 | B22: Aditya Mehta | C22: aditya.mehta.21@example.com | D22: Data Analyst Intern | E22: Company Website | F22: Recruiter A | G22: 46181 | K22: Applied | L22: In Progress | N22: =IFERROR(MATCH(K22,Lists!$A$2:$A$6,0),"") -> 1 | O22: =IF(OR(G22="",H22=""),"",H22-G22) | P22: =IF(OR(G22="",J22=""),"",J22-G22)
A23: C0022 | B23: Ishaan Mehta | C23: ishaan.mehta.22@example.com | D23: Software Engineering Intern | E23: Campus Drive | F23: Recruiter C | G23: 46236 | K23: Applied | L23: In Progress | N23: =IFERROR(MATCH(K23,Lists!$A$2:$A$6,0),"") -> 1 | O23: =IF(OR(G23="",H23=""),"",H23-G23) | P23: =IF(OR(G23="",J23=""),"",J23-G23)
A24: C0023 | B24: Aditya Khanna | C24: aditya.khanna.23@example.com | D24: Software Engineering Intern | E24: LinkedIn | F24: Recruiter C | G24: 46234 | K24: Applied | L24: Rejected | N24: =IFERROR(MATCH(K24,Lists!$A$2:$A$6,0),"") -> 1 | O24: =IF(OR(G24="",H24=""),"",H24-G24) | P24: =IF(OR(G24="",J24=""),"",J24-G24)
A25: C0024 | B25: Riya Iyer | C25: riya.iyer.24@example.com | D25: Data Analyst Intern | E25: LinkedIn | F25: Recruiter C | G25: 46233 | H25: 46234 | K25: Screened | L25: Rejected | N25: =IFERROR(MATCH(K25,Lists!$A$2:$A$6,0),"") -> 2 | O25: =IF(OR(G25="",H25=""),"",H25-G25) -> 1 | P25: =IF(OR(G25="",J25=""),"",J25-G25)
A26: C0025 | B26: Neel Kapoor | C26: neel.kapoor.25@example.com | D26: Operations Intern | E26: LinkedIn | F26: Recruiter B | G26: 46205 | H26: 46209 | I26: 46214 | J26: 46220 | K26: Offered | L26: In Progress | N26: =IFERROR(MATCH(K26,Lists!$A$2:$A$6,0),"") -> 4 | O26: =IF(OR(G26="",H26=""),"",H26-G26) -> 4 | P26: =IF(OR(G26="",J26=""),"",J26-G26) -> 15
A27: C0026 | B27: Anaya Reddy | C27: anaya.reddy.26@example.com | D27: Finance Intern | E27: Campus Drive | F27: Recruiter A | G27: 46230 | H27: 46232 | I27: 46234 | J27: 46241 | K27: Joined | L27: Joined | N27: =IFERROR(MATCH(K27,Lists!$A$2:$A$6,0),"") -> 5 | O27: =IF(OR(G27="",H27=""),"",H27-G27) -> 2 | P27: =IF(OR(G27="",J27=""),"",J27-G27) -> 11
A28: C0027 | B28: Anaya Gupta | C28: anaya.gupta.27@example.com | D28: Data Analyst Intern | E28: LinkedIn | F28: Recruiter A | G28: 46235 | H28: 46239 | K28: Screened | L28: Rejected | N28: =IFERROR(MATCH(K28,Lists!$A$2:$A$6,0),"") -> 2 | O28: =IF(OR(G28="",H28=""),"",H28-G28) -> 4 | P28: =IF(OR(G28="",J28=""),"",J28-G28)
A29: C0028 | B29: Yash Singh | C29: yash.singh.28@example.com | D29: Finance Intern | E29: Employee Referral | F29: Recruiter B | G29: 46232 | H29: 46237 | I29: 46245 | J29: 46252 | K29: Joined | L29: Joined | N29: =IFERROR(MATCH(K29,Lists!$A$2:$A$6,0),"") -> 5 | O29: =IF(OR(G29="",H29=""),"",H29-G29) -> 5 | P29: =IF(OR(G29="",J29=""),"",J29-G29) -> 20
A30: C0029 | B30: Rohan Mehta | C30: rohan.mehta.29@example.com | D30: Finance Intern | E30: LinkedIn | F30: Recruiter B | G30: 46181 | K30: Applied | L30: Rejected | N30: =IFERROR(MATCH(K30,Lists!$A$2:$A$6,0),"") -> 1 | O30: =IF(OR(G30="",H30=""),"",H30-G30) | P30: =IF(OR(G30="",J30=""),"",J30-G30)
A31: C0030 | B31: Diya Sharma | C31: diya.sharma.30@example.com | D31: Finance Intern | E31: LinkedIn | F31: Recruiter A | G31: 46238 | H31: 46241 | K31: Screened | L31: In Progress | N31: =IFERROR(MATCH(K31,Lists!$A$2:$A$6,0),"") -> 2 | O31: =IF(OR(G31="",H31=""),"",H31-G31) -> 3 | P31: =IF(OR(G31="",J31=""),"",J31-G31)
A32: C0031 | B32: Kabir Rao | C32: kabir.rao.31@example.com | D32: Finance Intern | E32: LinkedIn | F32: Recruiter C | G32: 46204 | K32: Applied | L32: Rejected | N32: =IFERROR(MATCH(K32,Lists!$A$2:$A$6,0),"") -> 1 | O32: =IF(OR(G32="",H32=""),"",H32-G32) | P32: =IF(OR(G32="",J32=""),"",J32-G32)
A33: C0032 | B33: Diya Rao | C33: diya.rao.32@example.com | D33: Marketing Intern | E33: Company Website | F33: Recruiter A | G33: 46248 | K33: Applied | L33: Rejected | N33: =IFERROR(MATCH(K33,Lists!$A$2:$A$6,0),"") -> 1 | O33: =IF(OR(G33="",H33=""),"",H33-G33) | P33: =IF(OR(G33="",J33=""),"",J33-G33)
A34: C0033 | B34: Neel Mehta | C34: neel.mehta.33@example.com | D34: Marketing Intern | E34: Job Portal | F34: Recruiter A | G34: 46190 | K34: Applied | L34: Rejected | N34: =IFERROR(MATCH(K34,Lists!$A$2:$A$6,0),"") -> 1 | O34: =IF(OR(G34="",H34=""),"",H34-G34) | P34: =IF(OR(G34="",J34=""),"",J34-G34)
A35: C0034 | B35: Aarav Khanna | C35: aarav.khanna.34@example.com | D35: Finance Intern | E35: LinkedIn | F35: Recruiter B | G35: 46246 | H35: 46248 | I35: 46251 | K35: Interviewed | L35: Rejected | N35: =IFERROR(MATCH(K35,Lists!$A$2:$A$6,0),"") -> 3 | O35: =IF(OR(G35="",H35=""),"",H35-G35) -> 2 | P35: =IF(OR(G35="",J35=""),"",J35-G35)
A36: C0035 | B36: Kabir Chopra | C36: kabir.chopra.35@example.com | D36: Finance Intern | E36: Campus Drive | F36: Recruiter C | G36: 46210 | K36: Applied | L36: In Progress | N36: =IFERROR(MATCH(K36,Lists!$A$2:$A$6,0),"") -> 1 | O36: =IF(OR(G36="",H36=""),"",H36-G36) | P36: =IF(OR(G36="",J36=""),"",J36-G36)
A37: C0036 | B37: Ishaan Sharma | C37: ishaan.sharma.36@example.com | D37: Software Engineering Intern | E37: LinkedIn | F37: Recruiter A | G37: 46244 | H37: 46249 | I37: 46252 | K37: Interviewed | L37: Withdrawn | N37: =IFERROR(MATCH(K37,Lists!$A$2:$A$6,0),"") -> 3 | O37: =IF(OR(G37="",H37=""),"",H37-G37) -> 5 | P37: =IF(OR(G37="",J37=""),"",J37-G37)
A38: C0037 | B38: Mira Gupta | C38: mira.gupta.37@example.com | D38: Software Engineering Intern | E38: Employee Referral | F38: Recruiter B | G38: 46200 | K38: Applied | L38: Rejected | N38: =IFERROR(MATCH(K38,Lists!$A$2:$A$6,0),"") -> 1 | O38: =IF(OR(G38="",H38=""),"",H38-G38) | P38: =IF(OR(G38="",J38=""),"",J38-G38)
A39: C0038 | B39: Ishaan Khanna | C39: ishaan.khanna.38@example.com | D39: Operations Intern | E39: Campus Drive | F39: Recruiter A | G39: 46180 | K39: Applied | L39: In Progress | N39: =IFERROR(MATCH(K39,Lists!$A$2:$A$6,0),"") -> 1 | O39: =IF(OR(G39="",H39=""),"",H39-G39) | P39: =IF(OR(G39="",J39=""),"",J39-G39)
A40: C0039 | B40: Aarav Iyer | C40: aarav.iyer.39@example.com | D40: Operations Intern | E40: Employee Referral | F40: Recruiter A | G40: 46207 | H40: 46210 | I40: 46219 | K40: Interviewed | L40: Rejected | N40: =IFERROR(MATCH(K40,Lists!$A$2:$A$6,0),"") -> 3 | O40: =IF(OR(G40="",H40=""),"",H40-G40) -> 3 | P40: =IF(OR(G40="",J40=""),"",J40-G40)
...

Sheet Read Me
A1: Recruitment Tracker: how to use
A3: Candidates sheet
A4: Blue text (columns A to M) is typed by the recruiter. Black text (columns N to P) is calculated. Do not overwrite black cells.
A5: Role, Source, Recruiter, Stage and Outcome use dropdown lists. Edit the allowed values on the Lists sheet.
A6: Stage = the furthest stage the candidate has reached. Outcome = the current status (In Progress, Rejected, Withdrawn, Joined).
A7: Add new candidates in the next empty row. Formulas and dropdowns are ready down to row 500.
A8: Amber Days to Screen means the candidate waited longer than the SLA set on the Dashboard (cell B4).
A10: Dashboard sheet
A11: Every number is a formula. Nothing needs refreshing. Yellow cell B4 is the only editable assumption.
A13: About the data
A14: All 120 candidates are synthetic (fictional names, example.com emails). Generated by src/generate_sample_data.py.

Sheet Lists
A1: Stage | B1: Outcome | C1: Role | D1: Source | E1: Recruiter
A2: Applied | B2: In Progress | C2: Data Analyst Intern | D2: LinkedIn | E2: Recruiter A
A3: Screened | B3: Rejected | C3: Software Engineering Intern | D3: Job Portal | E3: Recruiter B
A4: Interviewed | B4: Withdrawn | C4: Marketing Intern | D4: Employee Referral | E4: Recruiter C
A5: Offered | B5: Joined | C5: Operations Intern | D5: Campus Drive
A6: Joined | C6: Finance Intern | D6: Company Website
